Workbook

Sheet 1. Validador Automatico
A1: SISTEMA AUTOMÁTICO DE VALIDAÇÃO DE CADASTRO DE PRODUTOS AGRÍCOLAS (P.A., NCM, EMBALAGEM x NCM TIPI, MAPA E PIS/COFINS)
A2: COMO USAR: Preencha ou altere os Dados Básicos nas Colunas Azuis (A a H). As Colunas Automáticas [Auto] (I a X) consultam a Base Mestre (845 produtos) e o Dicionário (184 moléculas), extraem a embalagem da descrição e validam automaticamente Princípio Ativo, Unidade, NCM, Compatibilidade NCM x Embalagem (TIPI) e Registro MAPA.
A4: PRODUTOS EM VALIDAÇÃO | E4: CADASTROS 100% CONFORMES | I4: ERRO NCM x EMBALAGEM (TIPI) | M4: ERRO GERAL DE NCM (TIPI) | Q4: ERRO DE P.A. OU UNIDADE | U4: CADASTROS BLOQUEADOS (C/ ERRO)
A5: =COUNTA(B9:B73) -> 35 | E5: =COUNTIF(X9:X73,"CADASTRO 100% CONFORME*") -> 7 | I5: =COUNTIF(S9:S73,"INCOMPATÍVEL*") -> 11 | M5: =COUNTIF(R9:R73,"DIVERGENTE*") -> 18 | Q5: =COUNTIF(P9:P73,"DIVERGENTE*")+COUNTIF(M9:M73,"DIVERGENTE*") -> 9 | U5: =COUNTIF(X9:X73,"BLOQUEADO*") -> 28
A6: 35 pré-preenchidos + 30 linhas livres | E6: Prontos p/ liberação no ERP | I6: Faixa de peso/volume incompatível | M6: Subitem ou capítulo incorreto | Q6: Molécula ou unidade divergente | U6: Exigem saneamento imediato
A8: Código Produto | B8: Descrição do Produto (c/ Embalagem) | C8: Unidade Cadastrada | D8: Princípio Ativo Informado | E8: NCM Informada | F8: Código MAPA Informado | G8: Peso/Vol. Unitário Manual (kg/L) [Opcional] | H8: Cenário de Teste / Observação do Cadastro | I8: [Auto] Vínculo na Base de Conhecimento | J8: [Auto] Grupo e Sub-Grupo Oficial | K8: [Auto] Peso/Vol. Unitário Extraído (kg/L) | L8: [Auto] Unidade Física da Embalagem | M8: [Auto] Validação Unidade x Embalagem | N8: [Auto] Faixa de Embalagem TIPI | O8: [Auto] Princípio Ativo Oficial Correto (Bula) | P8: [Auto] Validação do Princípio Ativo | Q8: [Auto] NCM Oficial Exata (Molécula + Embalagem) | R8: [Auto] Validação Geral da NCM | S8: [Auto] Validação NCM x Embalagem Descrita (TIPI) | T8: [Auto] Código MAPA Oficial / Regra (Bula) | U8: [Auto] Validação do Código MAPA | V8: [Auto] Tributação PIS/COFINS (Até Mar/26 | Pós-Abr/26) | W8: [Auto] CST PIS/COFINS Recomendado | X8: [Auto] VEREDITO FINAL DO CADASTRO (TRAVA ERP)
A9: 4 | B9: 2-4 D AGCN 1X20L (IMP) TC | C9: L | D9: 2-4 D | E9: 3808.93.22 | F9: 315 | H9: Cenário 01 [OK]: Herbicida 2,4-D em embalagem 20L c/ NCM, P.A. e MAPA validados | I9: =IF(B9="","",IF(ISNUMBER(MATCH(A9,'4. Base Mestre (845 Produtos)'!$A$4:$A$848,0)),"Localizado por Código ("&A9&") na Base Mestre",IF(ISNUMBER(MATCH(B9,'4. Base Mestre (845 Produtos)'!$B$4:$B$848,0)),"Localizado por Descrição na Base Mestre",IF(ISNUMBER(MATCH(D9,'3. Dicionario Principios Ativos'!$A$4:$A$245,0)),"Produto Novo — Validado pelo Dicionário de P.A.","Não Localizado — Revisar Código/P.A.")))) -> Localizado por Código (4) na Base Mestre | J9: =IF(B9="","",IF(IF(ISNUMBER(MATCH(A9,'4. Base Mestre (845 Produtos)'!$A$4:$A$848,0)),MATCH(A9,'4. Base Mestre (845 Produtos)'!$A$4:$A$848,0),IF(ISNUMBER(MATCH(B9,'4. Base Mestre (845 Produtos)'!$B$4:$B$848,0)),MATCH(B9,'4. Base Mestre (845 Produtos)'!$B$4:$B$848,0),0))>0,INDEX('4. Base Mestre (845 Produtos)'!$I$4:$I$848,IF(ISNUMBER(MATCH(A9,'4. Base Mestre (845 Produtos)'!$A$4:$A$848,0)),MATCH(A9,'4. Base Mestre (845 Produtos)'!$A$4:$A$848,0),IF(ISNUMBER(MATCH(B9,'4. Base Mestre (845 Produtos)'!$B$4:$B$848,0)),MATCH(B9,'4. Base Mestre (845 Produtos)'!$B$4:$B$848,0),0))),IF(ISNUMBER(MATCH(D9,'3. Dicionario Principios Ativos'!$A$4:$A$245,0)),INDEX('3. Dicionario Principios Ativos'!$B$4:$B$245,MATCH(D9,'3. Dicionario Principios Ativos'!$A$4:$A$245,0)),"Revisar Classificação"))) -> Defensivos — Herbicida | K9: =IF(B9="","",IF(G9<>"",G9,IF(OR(ISNUMBER(SEARCH("PRINCIPIO ATIVO",B9)),ISNUMBER(SEARCH("PRINC. ATIVO",B9)),ISNUMBER(SEARCH("PR. ATIVO",B9)),ISNUMBER(SEARCH("PR.AT.",B9)),ISNUMBER(SEARCH("(P.A",B9)),ISNUMBER(SEARCH("(P. A",B9))),0,IF(OR(ISNUMBER(SEARCH("0,100KG",B9)),ISNUMBER(SEARCH("0,1KG",B9)),ISNUMBER(SEARCH("0,100L",B9))),0.1,IF(OR(ISNUMBER(SEARCH("0,200L",B9)),ISNUMBER(SEARCH("0,2L",B9)),ISNUMBER(SEARCH("0,200KG",B9)),ISNUMBER(SEARCH("0,2KG",B9))),0.2,IF(OR(ISNUMBER(SEARCH("0,240KG",B9)),ISNUMBER(SEARCH("0,250L",B9))),0.24,IF(OR(ISNUMBER(SEARCH("0,300KG",B9)),ISNUMBER(SEARCH("0,3KG",B9))),0.3,IF(OR(ISNUMBER(SEARCH("0,500L",B9)),ISNUMBER(SEARCH("0,5L",B9)),ISNUMBER(SEARCH("0,5KG",B9))),0.5,IF(ISNUMBER(SEARCH("0,8KG",B9)),0.8,IF(OR(ISNUMBER(SEARCH("1,5L",B9)),ISNUMBER(SEARCH("1,5KG",B9))),1.5,IF(OR(ISNUMBER(SEARCH("1,75L",B9)),ISNUMBER(SEARCH("1,8L",B9)),ISNUMBER(SEARCH("1.8L",B9))),1.8,IF(ISNUMBER(SEARCH("4,5KG",B9)),4.5,IF(ISNUMBER(SEARCH("7,5KG",B9)),7.5,IF(OR(ISNUMBER(SEARCH("1000L",B9)),ISNUMBER(SEARCH("1000KG",B9)),ISNUMBER(SEARCH("1.000KG",B9)),ISNUMBER(SEARCH("1.000L",B9)),ISNUMBER(SEARCH("1000 KG",B9)),ISNUMBER(SEARCH("GRANEL",B9)),ISNUMBER(SEARCH("(TON)",B9))),1000,IF(ISNUMBER(SEARCH("200L",B9)),200,IF(OR(ISNUMBER(SEARCH("25KG",B9)),ISNUMBER(SEARCH("25L",B9))),25,IF(OR(ISNUMBER(SEARCH("20L",B9)),ISNUMBER(SEARCH("20KG",B9))),20,IF(ISNUMBER(SEARCH("15KG",B9)),15,IF(OR(ISNUMBER(SEARCH("10L",B9)),ISNUMBER(SEARCH("10KG",B9))),10,IF(OR(ISNUMBER(SEARCH("5L",B9)),ISNUMBER(SEARCH("5KG",B9)),ISNUMBER(SEARCH("5LT",B9))),5,IF(OR(ISNUMBER(SEARCH("3KG",B9)),ISNUMBER(SEARCH("3L",B9))),3,IF(OR(ISNUMBER(SEARCH("2L",B9)),ISNUMBER(SEARCH("2KG",B9))),2,IF(OR(ISNUMBER(SEARCH("1L",B9)),ISNUMBER(SEARCH("1KG",B9)),ISNUMBER(SEARCH("1LT",B9))),1,IF(IF(ISNUMBER(MATCH(A9,'4. Base Mestre (845 Produtos)'!$A$4:$A$848,0)),MATCH(A9,'4. Base Mestre (845 Produtos)'!$A$4:$A$848,0),IF(ISNUMBER(MATCH(B9,'4. Base Mestre (845 Produtos)'!$B$4:$B$848,0)),MATCH(B9,'4. Base Mestre (845 Produtos)'!$B$4:$B$848,0),0))>0,INDEX('4. Base Mestre (845 Produtos)'!$D$4:$D$848,IF(ISNUMBER(MATCH(A9,'4. Base Mestre (845 Produtos)'!$A$4:$A$848,0)),MATCH(A9,'4. Base Mestre (845 Produtos)'!$A$4:$A$848,0),IF(ISNUMBER(MATCH(B9,'4. Base Mestre (845 Produtos)'!$B$4:$B$848,0)),MATCH(B9,'4. Base Mestre (845 Produtos)'!$B$4:$B$848,0),0))),1)))))))))))))))))))))))) -> 20 | L9: =IF(B9="","",IF(OR(ISNUMBER(SEARCH("KG",B9)),ISNUMBER(SEARCH("GR",B9))),"KG",IF(OR(ISNUMBER(SEARCH("0,200L",B9)),ISNUMBER(SEARCH("0,2L",B9)),ISNUMBER(SEARCH("0,5L",B9)),ISNUMBER(SEARCH("1,5L",B9)),ISNUMBER(SEARCH("1,8L",B9)),ISNUMBER(SEARCH("1.8L",B9)),ISNUMBER(SEARCH("1L",B9)),ISNUMBER(SEARCH("2L",B9)),ISNUMBER(SEARCH("3L",B9)),ISNUMBER(SEARCH("5L",B9)),ISNUMBER(SEARCH("10L",B9)),ISNUMBER(SEARCH("20L",B9)),ISNUMBER(SEARCH("25L",B9)),ISNUMBER(SEARCH("200L",B9)),ISNUMBER(SEARCH("1000L",B9)),ISNUMBER(SEARCH("LT",B9))),"L",IF(IF(ISNUMBER(MATCH(A9,'4. Base Mestre (845 Produtos)'!$A$4:$A$848,0)),MATCH(A9,'4. Base Mestre (845 Produtos)'!$A$4:$A$848,0),IF(ISNUMBER(MATCH(B9,'4. Base Mestre (845 Produtos)'!$B$4:$B$848,0)),MATCH(B9,'4. Base Mestre (845 Produtos)'!$B$4:$B$848,0),0))>0,INDEX('4. Base Mestre (845 Produtos)'!$E$4:$E$848,IF(ISNUMBER(MATCH(A9,'4. Base Mestre (845 Produtos)'!$A$4:$A$848,0)),MATCH(A9,'4. Base Mestre (845 Produtos)'!$A$4:$A$848,0),IF(ISNUMBER(MATCH(B9,'4. Base Mestre (845 Produtos)'!$B$4:$B$848,0)),MATCH(B9,'4. Base Mestre (845 Produtos)'!$B$4:$B$848,0),0))),C9)))) -> L | M9: =IF(B9="","",IF(C9=L9,"CONFORME — Unidade ("&C9&") compatível c/ Embalagem","DIVERGENTE — Embalagem em "&L9&", mas cadastrado em "&C9)) -> CONFORME — Unidade (L) compatível c/ Embalagem | N9: =IF(B9="","",IF(K9=0,"Granel / Produto Técnico (Sem Embalagem Comercial)",IF(K9<=0.3001,"Faixa 1 TIPI: Até 300g/mL (3808.61.00 / 3105.10.00)",IF(K9<=7.5001,"Faixa 2 TIPI: De 300g a 7,5kg/L (3808.62.90 / 3105.10.00)",IF(K9<=10.0001,"Faixa 3 TIPI: De 7,5kg a 10kg/L (3808.69.90 / 3105.10.00)","Faixa 4 TIPI: Acima de 10kg/L (3808.69.90 / Cap. 31 Geral)"))))) -> Faixa 4 TIPI: Acima de 10kg/L (3808.69.90 / Cap. 31 Geral) | O9: =IF(B9="","",IF(IF(ISNUMBER(MATCH(A9,'4. Base Mestre (845 Produtos)'!$A$4:$A$848,0)),MATCH(A9,'4. Base Mestre (845 Produtos)'!$A$4:$A$848,0),IF(ISNUMBER(MATCH(B9,'4. Base Mestre (845 Produtos)'!$B$4:$B$848,0)),MATCH(B9,'4. Base Mestre (845 Produtos)'!$B$4:$B$848,0),0))>0,INDEX('4. Base Mestre (845 Produtos)'!$H$4:$H$848,IF(ISNUMBER(MATCH(A9,'4. Base Mestre (845 Produtos)'!$A$4:$A$848,0)),MATCH(A9,'4. Base Mestre (845 Produtos)'!$A$4:$A$848,0),IF(ISNUMBER(MATCH(B9,'4. Base Mestre (845 Produtos)'!$B$4:$B$848,0)),MATCH(B9,'4. Base Mestre (845 Produtos)'!$B$4:$B$848,0),0))),IF(ISNUMBER(MATCH(D9,'3. Dicionario Principios Ativos'!$A$4:$A$245,0)),INDEX('3. Dicionario Principios Ativos'!$A$4:$A$245,MATCH(D9,'3. Dicionario Principios Ativos'!$A$4:$A$245,0)),D9))) -> 2-4 D | P9: =IF(B9="","",IF(D9=O9,"CONFORME — Princípio Ativo Validado","DIVERGENTE — Substituir por: "&O9)) -> CONFORME — Princípio Ativo Validado | Q9: =IF(B9="","",IF(IF(IF(ISNUMBER(MATCH(A9,'4. Base Mestre (845 Produtos)'!$A$4:$A$848,0)),MATCH(A9,'4. Base Mestre (845 Produtos)'!$A$4:$A$848,0),IF(ISNUMBER(MATCH(B9,'4. Base Mestre (845 Produtos)'!$B$4:$B$848,0)),MATCH(B9,'4. Base Mestre (845 Produtos)'!$B$4:$B$848,0),0))>0,INDEX('4. Base Mestre (845 Produtos)'!$J$4:$J$848,IF(ISNUMBER(MATCH(A9,'4. Base Mestre (845 Produtos)'!$A$4:$A$848,0)),MATCH(A9,'4. Base Mestre (845 Produtos)'!$A$4:$A$848,0),IF(ISNUMBER(MATCH(B9,'4. Base Mestre (845 Produtos)'!$B$4:$B$848,0)),MATCH(B9,'4. Base Mestre (845 Produtos)'!$B$4:$B$848,0),0)))="SIM",IF(ISNUMBER(MATCH(D9,'3. Dicionario Principios Ativos'!$A$4:$A$245,0)),INDEX('3. Dicionario Principios Ativos'!$C$4:$C$245,MATCH(D9,'3. Dicionario Principios Ativos'!$A$4:$A$245,0))="SIM",FALSE())),IF(AND(K9>0,K9<=0.3001),"3808.61.00",IF(AND(K9>0.3001,K9<=7.5001),"3808.62.90","3808.69.90")),IF(AND(LEFT(IF(IF(ISNUMBER(MATCH(A9,'4. Base Mestre (845 Produtos)'!$A$4:$A$848,0)),MATCH(A9,'4. Base Mestre (845 Produtos)'!$A$4:$A$848,0),IF(ISNUMBER(MATCH(B9,'4. Base Mestre (845 Produtos)'!$B$4:$B$848,0)),MATCH(B9,'4. Base Mestre (845 Produtos)'!$B$4:$B$848,0),0))>0,INDEX('4. Base Mestre (845 Produtos)'!$L$4:$L$848,IF(ISNUMBER(MATCH(A9,'4. Base Mestre (845 Produtos)'!$A$4:$A$848,0)),MATCH(A9,'4. Base Mestre (845 Produtos)'!$A$4:$A$848,0),IF(ISNUMBER(MATCH(B9,'4. Base Mestre (845 Produtos)'!$B$4:$B$848,0)),MATCH(B9,'4. Base Mestre (845 Produtos)'!$B$4:$B$848,0),0))),IF(ISNUMBER(MATCH(D9,'3. Dicionario Principios Ativos'!$A$4:$A$245,0)),INDEX('3. Dicionario Principios Ativos'!$D$4:$D$245,MATCH(D9,'3. Dicionario Principios Ativos'!$A$4:$A$245,0)),E9)),2)="31",E9="3105.10.00",K9>0,K9<=10.0001),"3105.10.00",IF(AND(IF(IF(ISNUMBER(MATCH(A9,'4. Base Mestre (845 Produtos)'!$A$4:$A$848,0)),MATCH(A9,'4. Base Mestre (845 Produtos)'!$A$4:$A$848,0),IF(ISNUMBER(MATCH(B9,'4. Base Mestre (845 Produtos)'!$B$4:$B$848,0)),MATCH(B9,'4. Base Mestre (845 Produtos)'!$B$4:$B$848,0),0))>0,INDEX('4. Base Mestre (845 Produtos)'!$L$4:$L$848,IF(ISNUMBER(MATCH(A9,'4. Base Mestre (845 Produtos)'!$A$4:$A$848,0)),MATCH(A9,'4. Base Mestre (845 Produtos)'!$A$4:$A$848,0),IF(ISNUMBER(MATCH(B9,'4. Base Mestre (845 Produtos)'!$B$4:$B$848,0)),MATCH(B9,'4. Base Mestre (845 Produtos)'!$B$4:$B$848,0),0))),IF(ISNUMBER(MATCH(D9,'3. Dicionario Principios Ativos'!$A$4:$A$245,0)),INDEX('3. Dicionario Principios Ativos'!$D$4:$D$245,MATCH(D9,'3. Dicionario Principios Ativos'!$A$4:$A$245,0)),E9))="3105.10.00",K9>10.0001),"3105.90.90",IF(IF(ISNUMBER(MATCH(A9,'4. Base Mestre (845 Produtos)'!$A$4:$A$848,0)),MATCH(A9,'4. Base Mestre (845 Produtos)'!$A$4:$A$848,0),IF(ISNUMBER(MATCH(B9,'4. Base Mestre (845 Produtos)'!$B$4:$B$848,0)),MATCH(B9,'4. Base Mestre (845 Produtos)'!$B$4:$B$848,0),0))>0,INDEX('4. Base Mestre (845 Produtos)'!$L$4:$L$848,IF(ISNUMBER(MATCH(A9,'4. Base Mestre (845 Produtos)'!$A$4:$A$848,0)),MATCH(A9,'4. Base Mestre (845 Produtos)'!$A$4:$A$848,0),IF(ISNUMBER(MATCH(B9,'4. Base Mestre (845 Produtos)'!$B$4:$B$848,0)),MATCH(B9,'4. Base Mestre (845 Produtos)'!$B$4:$B$848,0),0))),IF(ISNUMBER(MATCH(D9,'3. Dicionario Principios Ativos'!$A$4:$A$245,0)),INDEX('3. Dicionario Principios Ativos'!$D$4:$D$245,MATCH(D9,'3. Dicionario Principios Ativos'!$A$4:$A$245,0)),E9)))))) -> 3808.93.22 | R9: =IF(B9="","",IF(OR(E9=Q9,AND(Q9="3002.49.99",E9="3002.90.00")),"CONFORME — NCM "&E9&" Correta na TIPI","DIVERGENTE — Substituir "&E9&" por "&Q9)) -> CONFORME — NCM 3808.93.22 Correta na TIPI | S9: =IF(B9="","",IF(AND(E9="3808.61.00",OR(K9>0.3001,K9=0)),"INCOMPATÍVEL — NCM 3808.61.00 exige emb. <= 0,3kg/L (Emb. atual: "&K9&" "&L9&" -> usar "&Q9&")",IF(AND(LEFT(E9,7)="3808.62",OR(K9<=0.3001,K9>7.5001)),"INCOMPATÍVEL — NCM 3808.62 exige emb. de 0,3 a 7,5kg/L (Emb. atual: "&K9&" "&L9&" -> usar "&Q9&")",IF(AND(LEFT(E9,7)="3808.69",K9>0,K9<=7.5001),"INCOMPATÍVEL — NCM 3808.69 exige emb. > 7,5kg/L (Emb. atual: "&K9&" "&L9&" -> usar "&Q9&")",IF(AND(LEFT(Q9,6)="3808.6",LEFT(E9,6)<>"3808.6"),"INCOMPATÍVEL — Molécula Nota Subpos. 2 c/ emb. "&K9&" "&L9&" exige NCM "&Q9,IF(AND(OR(E9="3808.91.19",E9="3808.92.19",E9="3808.93.19",E9="3808.99.19"),K9>=1),"INCOMPATÍVEL — Subitem .19 (Domissanitário) vedado p/ emb. agrícola de "&K9&" "&L9,IF(AND(E9="3105.10.00",K9>10.0001),"INCOMPATÍVEL — NCM 3105.10.00 exige peso bruto <= 10kg (Emb. atual: "&K9&" "&L9&" -> usar 3105.90.90)",IF(AND(LEFT(E9,2)="29",LEFT(Q9,4)="3808",K9>0),"INCOMPATÍVEL — Produto formulado em emb. comercial ("&K9&" "&L9&") vedado no Cap. 29 -> usar "&Q9,"CONFORME — Embalagem ("&K9&" "&L9&") compatível c/ a NCM")))))))) -> CONFORME — Embalagem (20 L) compatível c/ a NCM | T9: =IF(B9="","",IF(IF(ISNUMBER(MATCH(A9,'4. Base Mestre (845 Produtos)'!$A$4:$A$848,0)),MATCH(A9,'4. Base Mestre (845 Produtos)'!$A$4:$A$848,0),IF(ISNUMBER(MATCH(B9,'4. Base Mestre (845 Produtos)'!$B$4:$B$848,0)),MATCH(B9,'4. Base Mestre (845 Produtos)'!$B$4:$B$848,0),0))>0,INDEX('4. Base Mestre (845 Produtos)'!$P$4:$P$848,IF(ISNUMBER(MATCH(A9,'4. Base Mestre (845 Produtos)'!$A$4:$A$848,0)),MATCH(A9,'4. Base Mestre (845 Produtos)'!$A$4:$A$848,0),IF(ISNUMBER(MATCH(B9,'4. Base Mestre (845 Produtos)'!$B$4:$B$848,0)),MATCH(B9,'4. Base Mestre (845 Produtos)'!$B$4:$B$848,0),0))),IF(ISNUMBER(MATCH(D9,'3. Dicionario Principios Ativos'!$A$4:$A$245,0)),INDEX('3. Dicionario Principios Ativos'!$K$4:$K$245,MATCH(D9,'3. Dicionario Principios Ativos'!$A$4:$A$245,0)),"VERIFICAR BULA"))) -> 315 | U9: =IF(B9="","",IF(ISNUMBER(SEARCH("ISENTO",T9)),IF(OR(F9=0,F9="0",F9="ISENTO",F9=""),"CONFORME (DISPENSADO) — Isento pelo Ato SDA/MAPA nº 104/2017","INCORRETO — Produto isento de registro MAPA (usar 0 ou ISENTO)"),IF(ISNUMBER(SEARCH("SIPEAGRO",T9)),IF(ISNUMBER(SEARCH("-",F9)),"CONFORME — Registro SIPEAGRO ("&F9&") Preenchido","ADEQUAR P/ SIPEAGRO — Substituir 0 pelo Registro (UF-XXXXX-XXXXX.X)"),IF(ISNUMBER(SEARCH("VINCULAR",T9)),IF(AND(F9<>0,F9<>"0",F9<>""),"INCORRETO / TROCADO — Código "&F9&" pertence a outro produto (Vincular bula da marca)","VINCULAR MARCA — Cadastro de P.A. s/ marca fixa (Vincular registro na NF-e)"),IF(OR(F9=0,F9="0",F9=""),"AUSENTE (ZERO) — Preencher Registro Oficial MAPA nº "&T9,IF(TEXT(F9,"0")=TEXT(T9,"0"),"CONFORME — Registro MAPA nº "&T9&" Validado na Bula","INCORRETO / TROCADO — Substituir "&F9&" pelo Registro Oficial nº "&T9)))))) -> CONFORME — Registro MAPA nº 315 Validado na Bula | V9: =IF(B9="","",IF(IF(ISNUMBER(MATCH(A9,'4. Base Mestre (845 Produtos)'!$A$4:$A$848,0)),MATCH(A9,'4. Base Mestre (845 Produtos)'!$A$4:$A$848,0),IF(ISNUMBER(MATCH(B9,'4. Base Mestre (845 Produtos)'!$B$4:$B$848,0)),MATCH(B9,'4. Base Mestre (845 Produtos)'!$B$4:$B$848,0),0))>0,INDEX('4. Base Mestre (845 Produtos)'!$S$4:$S$848,IF(ISNUMBER(MATCH(A9,'4. Base Mestre (845 Produtos)'!$A$4:$A$848,0)),MATCH(A9,'4. Base Mestre (845 Produtos)'!$A$4:$A$848,0),IF(ISNUMBER(MATCH(B9,'4. Base Mestre (845 Produtos)'!$B$4:$B$848,0)),MATCH(B9,'4. Base Mestre (845 Produtos)'!$B$4:$B$848,0),0))),IF(ISNUMBER(MATCH(D9,'3. Dicionario Principios Ativos'!$A$4:$A$245,0)),INDEX('3. Dicionario Principios Ativos'!$L$4:$L$245,MATCH(D9,'3. Dicionario Principios Ativos'!$A$4:$A$245,0)),"Verificar NCM"))) -> Beneficiado (Lei 10.925/04): 0% até Mar/26 | 0,925% Real / 0,365% Pres. pós-Abr/26 (LC 224/25) | W9: =IF(B9="","",IF(IF(ISNUMBER(MATCH(A9,'4. Base Mestre (845 Produtos)'!$A$4:$A$848,0)),MATCH(A9,'4. Base Mestre (845 Produtos)'!$A$4:$A$848,0),IF(ISNUMBER(MATCH(B9,'4. Base Mestre (845 Produtos)'!$B$4:$B$848,0)),MATCH(B9,'4. Base Mestre (845 Produtos)'!$B$4:$B$848,0),0))>0,INDEX('4. Base Mestre (845 Produtos)'!$T$4:$T$848,IF(ISNUMBER(MATCH(A9,'4. Base Mestre (845 Produtos)'!$A$4:$A$848,0)),MATCH(A9,'4. Base Mestre (845 Produtos)'!$A$4:$A$848,0),IF(ISNUMBER(MATCH(B9,'4. Base Mestre (845 Produtos)'!$B$4:$B$848,0)),MATCH(B9,'4. Base Mestre (845 Produtos)'!$B$4:$B$848,0),0))),IF(ISNUMBER(MATCH(D9,'3. Dicionario Principios Ativos'!$A$4:$A$245,0)),INDEX('3. Dicionario Principios Ativos'!$M$4:$M$245,MATCH(D9,'3. Dicionario Principios Ativos'!$A$4:$A$245,0)),"Verificar CST"))) -> Saída: CST 06 (c/ Ajuste M220/M620 pós-Abr/26) | Entrada Revenda: CST 73 | X9: =IF(B9="","",IF(AND(LEFT(M9,8)="CONFORME",LEFT(P9,8)="CONFORME",LEFT(R9,8)="CONFORME",LEFT(S9,8)="CONFORME",LEFT(U9,8)="CONFORME"),"CADASTRO 100% CONFORME — LIBERADO P/ ERP",IF(AND(LEFT(M9,8)="CONFORME",LEFT(P9,8)="CONFORME",LEFT(R9,8)="CONFORME",LEFT(S9,8)="CONFORME",OR(LEFT(U9,7)="ADEQUAR",LEFT(U9,8)="VINCULAR")),"FISCAL E EMBALAGEM OK — ADEQUAR CAMPO MAPA (SIPEAGRO / MARCA)","BLOQUEADO — CORRIGIR DIVERGÊNCIAS APONTADAS ANTES DE LIBERAR NO ERP"))) -> CADASTRO 100% CONFORME — LIBERADO P/ ERP
A10: 4290 | B10: IMPACTUS CS 0,200L (IMP) AMOSTRA | C10: L | D10: LAMBDA-CIALOTRINA 250 | E10: 3808.61.00 | F10: 12225 | H10: Cenário 02 [OK]: Lambda-cialotrina em amostra 0,200L (<=300mL) na NCM 3808.61.00 correta | I10: =IF(B10="","",IF(ISNUMBER(MATCH(A10,'4. Base Mestre (845 Produtos)'!$A$4:$A$848,0)),"Localizado por Código ("&A10&") na Base Mestre",IF(ISNUMBER(MATCH(B10,'4. Base Mestre (845 Produtos)'!$B$4:$B$848,0)),"Localizado por Descrição na Base Mestre",IF(ISNUMBER(MATCH(D10,'3. Dicionario Principios Ativos'!$A$4:$A$245,0)),"Produto Novo — Validado pelo Dicionário de P.A.","Não Localizado — Revisar Código/P.A.")))) -> Localizado por Código (4290) na Base Mestre | J10: =IF(B10="","",IF(IF(ISNUMBER(MATCH(A10,'4. Base Mestre (845 Produtos)'!$A$4:$A$848,0)),MATCH(A10,'4. Base Mestre (845 Produtos)'!$A$4:$A$848,0),IF(ISNUMBER(MATCH(B10,'4. Base Mestre (845 Produtos)'!$B$4:$B$848,0)),MATCH(B10,'4. Base Mestre (845 Produtos)'!$B$4:$B$848,0),0))>0,INDEX('4. Base Mestre (845 Produtos)'!$I$4:$I$848,IF(ISNUMBER(MATCH(A10,'4. Base Mestre (845 Produtos)'!$A$4:$A$848,0)),MATCH(A10,'4. Base Mestre (845 Produtos)'!$A$4:$A$848,0),IF(ISNUMBER(MATCH(B10,'4. Base Mestre (845 Produtos)'!$B$4:$B$848,0)),MATCH(B10,'4. Base Mestre (845 Produtos)'!$B$4:$B$848,0),0))),IF(ISNUMBER(MATCH(D10,'3. Dicionario Principios Ativos'!$A$4:$A$245,0)),INDEX('3. Dicionario Principios Ativos'!$B$4:$B$245,MATCH(D10,'3. Dicionario Principios Ativos'!$A$4:$A$245,0)),"Revisar Classificação"))) -> Defensivos — Inseticida | K10: =IF(B10="","",IF(G10<>"",G10,IF(OR(ISNUMBER(SEARCH("PRINCIPIO ATIVO",B10)),ISNUMBER(SEARCH("PRINC. ATIVO",B10)),ISNUMBER(SEARCH("PR. ATIVO",B10)),ISNUMBER(SEARCH("PR.AT.",B10)),ISNUMBER(SEARCH("(P.A",B10)),ISNUMBER(SEARCH("(P. A",B10))),0,IF(OR(ISNUMBER(SEARCH("0,100KG",B10)),ISNUMBER(SEARCH("0,1KG",B10)),ISNUMBER(SEARCH("0,100L",B10))),0.1,IF(OR(ISNUMBER(SEARCH("0,200L",B10)),ISNUMBER(SEARCH("0,2L",B10)),ISNUMBER(SEARCH("0,200KG",B10)),ISNUMBER(SEARCH("0,2KG",B10))),0.2,IF(OR(ISNUMBER(SEARCH("0,240KG",B10)),ISNUMBER(SEARCH("0,250L",B10))),0.24,IF(OR(ISNUMBER(SEARCH("0,300KG",B10)),ISNUMBER(SEARCH("0,3KG",B10))),0.3,IF(OR(ISNUMBER(SEARCH("0,500L",B10)),ISNUMBER(SEARCH("0,5L",B10)),ISNUMBER(SEARCH("0,5KG",B10))),0.5,IF(ISNUMBER(SEARCH("0,8KG",B10)),0.8,IF(OR(ISNUMBER(SEARCH("1,5L",B10)),ISNUMBER(SEARCH("1,5KG",B10))),1.5,IF(OR(ISNUMBER(SEARCH("1,75L",B10)),ISNUMBER(SEARCH("1,8L",B10)),ISNUMBER(SEARCH("1.8L",B10))),1.8,IF(ISNUMBER(SEARCH("4,5KG",B10)),4.5,IF(ISNUMBER(SEARCH("7,5KG",B10)),7.5,IF(OR(ISNUMBER(SEARCH("1000L",B10)),ISNUMBER(SEARCH("1000KG",B10)),ISNUMBER(SEARCH("1.000KG",B10)),ISNUMBER(SEARCH("1.000L",B10)),ISNUMBER(SEARCH("1000 KG",B10)),ISNUMBER(SEARCH("GRANEL",B10)),ISNUMBER(SEARCH("(TON)",B10))),1000,IF(ISNUMBER(SEARCH("200L",B10)),200,IF(OR(ISNUMBER(SEARCH("25KG",B10)),ISNUMBER(SEARCH("25L",B10))),25,IF(OR(ISNUMBER(SEARCH("20L",B10)),ISNUMBER(SEARCH("20KG",B10))),20,IF(ISNUMBER(SEARCH("15KG",B10)),15,IF(OR(ISNUMBER(SEARCH("10L",B10)),ISNUMBER(SEARCH("10KG",B10))),10,IF(OR(ISNUMBER(SEARCH("5L",B10)),ISNUMBER(SEARCH("5KG",B10)),ISNUMBER(SEARCH("5LT",B10))),5,IF(OR(ISNUMBER(SEARCH("3KG",B10)),ISNUMBER(SEARCH("3L",B10))),3,IF(OR(ISNUMBER(SEARCH("2L",B10)),ISNUMBER(SEARCH("2KG",B10))),2,IF(OR(ISNUMBER(SEARCH("1L",B10)),ISNUMBER(SEARCH("1KG",B10)),ISNUMBER(SEARCH("1LT",B10))),1,IF(IF(ISNUMBER(MATCH(A10,'4. Base Mestre (845 Produtos)'!$A$4:$A$848,0)),MATCH(A10,'4. Base Mestre (845 Produtos)'!$A$4:$A$848,0),IF(ISNUMBER(MATCH(B10,'4. Base Mestre (845 Produtos)'!$B$4:$B$848,0)),MATCH(B10,'4. Base Mestre (845 Produtos)'!$B$4:$B$848,0),0))>0,INDEX('4. Base Mestre (845 Produtos)'!$D$4:$D$848,IF(ISNUMBER(MATCH(A10,'4. Base Mestre (845 Produtos)'!$A$4:$A$848,0)),MATCH(A10,'4. Base Mestre (845 Produtos)'!$A$4:$A$848,0),IF(ISNUMBER(MATCH(B10,'4. Base Mestre (845 Produtos)'!$B$4:$B$848,0)),MATCH(B10,'4. Base Mestre (845 Produtos)'!$B$4:$B$848,0),0))),1)))))))))))))))))))))))) -> 0.2 | L10: =IF(B10="","",IF(OR(ISNUMBER(SEARCH("KG",B10)),ISNUMBER(SEARCH("GR",B10))),"KG",IF(OR(ISNUMBER(SEARCH("0,200L",B10)),ISNUMBER(SEARCH("0,2L",B10)),ISNUMBER(SEARCH("0,5L",B10)),ISNUMBER(SEARCH("1,5L",B10)),ISNUMBER(SEARCH("1,8L",B10)),ISNUMBER(SEARCH("1.8L",B10)),ISNUMBER(SEARCH("1L",B10)),ISNUMBER(SEARCH("2L",B10)),ISNUMBER(SEARCH("3L",B10)),ISNUMBER(SEARCH("5L",B10)),ISNUMBER(SEARCH("10L",B10)),ISNUMBER(SEARCH("20L",B10)),ISNUMBER(SEARCH("25L",B10)),ISNUMBER(SEARCH("200L",B10)),ISNUMBER(SEARCH("1000L",B10)),ISNUMBER(SEARCH("LT",B10))),"L",IF(IF(ISNUMBER(MATCH(A10,'4. Base Mestre (845 Produtos)'!$A$4:$A$848,0)),MATCH(A10,'4. Base Mestre (845 Produtos)'!$A$4:$A$848,0),IF(ISNUMBER(MATCH(B10,'4. Base Mestre (845 Produtos)'!$B$4:$B$848,0)),MATCH(B10,'4. Base Mestre (845 Produtos)'!$B$4:$B$848,0),0))>0,INDEX('4. Base Mestre (845 Produtos)'!$E$4:$E$848,IF(ISNUMBER(MATCH(A10,'4. Base Mestre (845 Produtos)'!$A$4:$A$848,0)),MATCH(A10,'4. Base Mestre (845 Produtos)'!$A$4:$A$848,0),IF(ISNUMBER(MATCH(B10,'4. Base Mestre (845 Produtos)'!$B$4:$B$848,0)),MATCH(B10,'4. Base Mestre (845 Produtos)'!$B$4:$B$848,0),0))),C10)))) -> L | M10: =IF(B10="","",IF(C10=L10,"CONFORME — Unidade ("&C10&") compatível c/ Embalagem","DIVERGENTE — Embalagem em "&L10&", mas cadastrado em "&C10)) -> CONFORME — Unidade (L) compatível c/ Embalagem | N10: =IF(B10="","",IF(K10=0,"Granel / Produto Técnico (Sem Embalagem Comercial)",IF(K10<=0.3001,"Faixa 1 TIPI: Até 300g/mL (3808.61.00 / 3105.10.00)",IF(K10<=7.5001,"Faixa 2 TIPI: De 300g a 7,5kg/L (3808.62.90 / 3105.10.00)",IF(K10<=10.0001,"Faixa 3 TIPI: De 7,5kg a 10kg/L (3808.69.90 / 3105.10.00)","Faixa 4 TIPI: Acima de 10kg/L (3808.69.90 / Cap. 31 Geral)"))))) -> Faixa 1 TIPI: Até 300g/mL (3808.61.00 / 3105.10.00) | O10: =IF(B10="","",IF(IF(ISNUMBER(MATCH(A10,'4. Base Mestre (845 Produtos)'!$A$4:$A$848,0)),MATCH(A10,'4. Base Mestre (845 Produtos)'!$A$4:$A$848,0),IF(ISNUMBER(MATCH(B10,'4. Base Mestre (845 Produtos)'!$B$4:$B$848,0)),MATCH(B10,'4. Base Mestre (845 Produtos)'!$B$4:$B$848,0),0))>0,INDEX('4. Base Mestre (845 Produtos)'!$H$4:$H$848,IF(ISNUMBER(MATCH(A10,'4. Base Mestre (845 Produtos)'!$A$4:$A$848,0)),MATCH(A10,'4. Base Mestre (845 Produtos)'!$A$4:$A$848,0),IF(ISNUMBER(MATCH(B10,'4. Base Mestre (845 Produtos)'!$B$4:$B$848,0)),MATCH(B10,'4. Base Mestre (845 Produtos)'!$B$4:$B$848,0),0))),IF(ISNUMBER(MATCH(D10,'3. Dicionario Principios Ativos'!$A$4:$A$245,0)),INDEX('3. Dicionario Principios Ativos'!$A$4:$A$245,MATCH(D10,'3. Dicionario Principios Ativos'!$A$4:$A$245,0)),D10))) -> LAMBDA-CIALOTRINA 250 | P10: =IF(B10="","",IF(D10=O10,"CONFORME — Princípio Ativo Validado","DIVERGENTE — Substituir por: "&O10)) -> CONFORME — Princípio Ativo Validado | Q10: =IF(B10="","",IF(IF(IF(ISNUMBER(MATCH(A10,'4. Base Mestre (845 Produtos)'!$A$4:$A$848,0)),MATCH(A10,'4. Base Mestre (845 Produtos)'!$A$4:$A$848,0),IF(ISNUMBER(MATCH(B10,'4. Base Mestre (845 Produtos)'!$B$4:$B$848,0)),MATCH(B10,'4. Base Mestre (845 Produtos)'!$B$4:$B$848,0),0))>0,INDEX('4. Base Mestre (845 Produtos)'!$J$4:$J$848,IF(ISNUMBER(MATCH(A10,'4. Base Mestre (845 Produtos)'!$A$4:$A$848,0)),MATCH(A10,'4. Base Mestre (845 Produtos)'!$A$4:$A$848,0),IF(ISNUMBER(MATCH(B10,'4. Base Mestre (845 Produtos)'!$B$4:$B$848,0)),MATCH(B10,'4. Base Mestre (845 Produtos)'!$B$4:$B$848,0),0)))="SIM",IF(ISNUMBER(MATCH(D10,'3. Dicionario Principios Ativos'!$A$4:$A$245,0)),INDEX('3. Dicionario Principios Ativos'!$C$4:$C$245,MATCH(D10,'3. Dicionario Principios Ativos'!$A$4:$A$245,0))="SIM",FALSE())),IF(AND(K10>0,K10<=0.3001),"3808.61.00",IF(AND(K10>0.3001,K10<=7.5001),"3808.62.90","3808.69.90")),IF(AND(LEFT(IF(IF(ISNUMBER(MATCH(A10,'4. Base Mestre (845 Produtos)'!$A$4:$A$848,0)),MATCH(A10,'4. Base Mestre (845 Produtos)'!$A$4:$A$848,0),IF(ISNUMBER(MATCH(B10,'4. Base Mestre (845 Produtos)'!$B$4:$B$848,0)),MATCH(B10,'4. Base Mestre (845 Produtos)'!$B$4:$B$848,0),0))>0,INDEX('4. Base Mestre (845 Produtos)'!$L$4:$L$848,IF(ISNUMBER(MATCH(A10,'4. Base Mestre (845 Produtos)'!$A$4:$A$848,0)),MATCH(A10,'4. Base Mestre (845 Produtos)'!$A$4:$A$848,0),IF(ISNUMBER(MATCH(B10,'4. Base Mestre (845 Produtos)'!$B$4:$B$848,0)),MATCH(B10,'4. Base Mestre (845 Produtos)'!$B$4:$B$848,0),0))),IF(ISNUMBER(MATCH(D10,'3. Dicionario Principios Ativos'!$A$4:$A$245,0)),INDEX('3. Dicionario Principios Ativos'!$D$4:$D$245,MATCH(D10,'3. Dicionario Principios Ativos'!$A$4:$A$245,0)),E10)),2)="31",E10="3105.10.00",K10>0,K10<=10.0001),"3105.10.00",IF(AND(IF(IF(ISNUMBER(MATCH(A10,'4. Base Mestre (845 Produtos)'!$A$4:$A$848,0)),MATCH(A10,'4. Base Mestre (845 Produtos)'!$A$4:$A$848,0),IF(ISNUMBER(MATCH(B10,'4. Base Mestre (845 Produtos)'!$B$4:$B$848,0)),MATCH(B10,'4. Base Mestre (845 Produtos)'!$B$4:$B$848,0),0))>0,INDEX('4. Base Mestre (845 Produtos)'!$L$4:$L$848,IF(ISNUMBER(MATCH(A10,'4. Base Mestre (845 Produtos)'!$A$4:$A$848,0)),MATCH(A10,'4. Base Mestre (845 Produtos)'!$A$4:$A$848,0),IF(ISNUMBER(MATCH(B10,'4. Base Mestre (845 Produtos)'!$B$4:$B$848,0)),MATCH(B10,'4. Base Mestre (845 Produtos)'!$B$4:$B$848,0),0))),IF(ISNUMBER(MATCH(D10,'3. Dicionario Principios Ativos'!$A$4:$A$245,0)),INDEX('3. Dicionario Principios Ativos'!$D$4:$D$245,MATCH(D10,'3. Dicionario Principios Ativos'!$A$4:$A$245,0)),E10))="3105.10.00",K10>10.0001),"3105.90.90",IF(IF(ISNUMBER(MATCH(A10,'4. Base Mestre (845 Produtos)'!$A$4:$A$848,0)),MATCH(A10,'4. Base Mestre (845 Produtos)'!$A$4:$A$848,0),IF(ISNUMBER(MATCH(B10,'4. Base Mestre (845 Produtos)'!$B$4:$B$848,0)),MATCH(B10,'4. Base Mestre (845 Produtos)'!$B$4:$B$848,0),0))>0,INDEX('4. Base Mestre (845 Produtos)'!$L$4:$L$848,IF(ISNUMBER(MATCH(A10,'4. Base Mestre (845 Produtos)'!$A$4:$A$848,0)),MATCH(A10,'4. Base Mestre (845 Produtos)'!$A$4:$A$848,0),IF(ISNUMBER(MATCH(B10,'4. Base Mestre (845 Produtos)'!$B$4:$B$848,0)),MATCH(B10,'4. Base Mestre (845 Produtos)'!$B$4:$B$848,0),0))),IF(ISNUMBER(MATCH(D10,'3. Dicionario Principios Ativos'!$A$4:$A$245,0)),INDEX('3. Dicionario Principios Ativos'!$D$4:$D$245,MATCH(D10,'3. Dicionario Principios Ativos'!$A$4:$A$245,0)),E10)))))) -> 3808.61.00 | R10: =IF(B10="","",IF(OR(E10=Q10,AND(Q10="3002.49.99",E10="3002.90.00")),"CONFORME — NCM "&E10&" Correta na TIPI","DIVERGENTE — Substituir "&E10&" por "&Q10)) -> CONFORME — NCM 3808.61.00 Correta na TIPI | S10: =IF(B10="","",IF(AND(E10="3808.61.00",OR(K10>0.3001,K10=0)),"INCOMPATÍVEL — NCM 3808.61.00 exige emb. <= 0,3kg/L (Emb. atual: "&K10&" "&L10&" -> usar "&Q10&")",IF(AND(LEFT(E10,7)="3808.62",OR(K10<=0.3001,K10>7.5001)),"INCOMPATÍVEL — NCM 3808.62 exige emb. de 0,3 a 7,5kg/L (Emb. atual: "&K10&" "&L10&" -> usar "&Q10&")",IF(AND(LEFT(E10,7)="3808.69",K10>0,K10<=7.5001),"INCOMPATÍVEL — NCM 3808.69 exige emb. > 7,5kg/L (Emb. atual: "&K10&" "&L10&" -> usar "&Q10&")",IF(AND(LEFT(Q10,6)="3808.6",LEFT(E10,6)<>"3808.6"),"INCOMPATÍVEL — Molécula Nota Subpos. 2 c/ emb. "&K10&" "&L10&" exige NCM "&Q10,IF(AND(OR(E10="3808.91.19",E10="3808.92.19",E10="3808.93.19",E10="3808.99.19"),K10>=1),"INCOMPATÍVEL — Subitem .19 (Domissanitário) vedado p/ emb. agrícola de "&K10&" "&L10,IF(AND(E10="3105.10.00",K10>10.0001),"INCOMPATÍVEL — NCM 3105.10.00 exige peso bruto <= 10kg (Emb. atual: "&K10&" "&L10&" -> usar 3105.90.90)",IF(AND(LEFT(E10,2)="29",LEFT(Q10,4)="3808",K10>0),"INCOMPATÍVEL — Produto formulado em emb. comercial ("&K10&" "&L10&") vedado no Cap. 29 -> usar "&Q10,"CONFORME — Embalagem ("&K10&" "&L10&") compatível c/ a NCM")))))))) -> CONFORME — Embalagem (0.2 L) compatível c/ a NCM | T10: =IF(B10="","",IF(IF(ISNUMBER(MATCH(A10,'4. Base Mestre (845 Produtos)'!$A$4:$A$848,0)),MATCH(A10,'4. Base Mestre (845 Produtos)'!$A$4:$A$848,0),IF(ISNUMBER(MATCH(B10,'4. Base Mestre (845 Produtos)'!$B$4:$B$848,0)),MATCH(B10,'4. Base Mestre (845 Produtos)'!$B$4:$B$848,0),0))>0,INDEX('4. Base Mestre (845 Produtos)'!$P$4:$P$848,IF(ISNUMBER(MATCH(A10,'4. Base Mestre (845 Produtos)'!$A$4:$A$848,0)),MATCH(A10,'4. Base Mestre (845 Produtos)'!$A$4:$A$848,0),IF(ISNUMBER(MATCH(B10,'4. Base Mestre (845 Produtos)'!$B$4:$B$848,0)),MATCH(B10,'4. Base Mestre (845 Produtos)'!$B$4:$B$848,0),0))),IF(ISNUMBER(MATCH(D10,'3. Dicionario Principios Ativos'!$A$4:$A$245,0)),INDEX('3. Dicionario Principios Ativos'!$K$4:$K$245,MATCH(D10,'3. Dicionario Principios Ativos'!$A$4:$A$245,0)),"VERIFICAR BULA"))) -> 12225 | U10: =IF(B10="","",IF(ISNUMBER(SEARCH("ISENTO",T10)),IF(OR(F10=0,F10="0",F10="ISENTO",F10=""),"CONFORME (DISPENSADO) — Isento pelo Ato SDA/MAPA nº 104/2017","INCORRETO — Produto isento de registro MAPA (usar 0 ou ISENTO)"),IF(ISNUMBER(SEARCH("SIPEAGRO",T10)),IF(ISNUMBER(SEARCH("-",F10)),"CONFORME — Registro SIPEAGRO ("&F10&") Preenchido","ADEQUAR P/ SIPEAGRO — Substituir 0 pelo Registro (UF-XXXXX-XXXXX.X)"),IF(ISNUMBER(SEARCH("VINCULAR",T10)),IF(AND(F10<>0,F10<>"0",F10<>""),"INCORRETO / TROCADO — Código "&F10&" pertence a outro produto (Vincular bula da marca)","VINCULAR MARCA — Cadastro de P.A. s/ marca fixa (Vincular registro na NF-e)"),IF(OR(F10=0,F10="0",F10=""),"AUSENTE (ZERO) — Preencher Registro Oficial MAPA nº "&T10,IF(TEXT(F10,"0")=TEXT(T10,"0"),"CONFORME — Registro MAPA nº "&T10&" Validado na Bula","INCORRETO / TROCADO — Substituir "&F10&" pelo Registro Oficial nº "&T10)))))) -> CONFORME — Registro MAPA nº 12225 Validado na Bula | V10: =IF(B10="","",IF(IF(ISNUMBER(MATCH(A10,'4. Base Mestre (845 Produtos)'!$A$4:$A$848,0)),MATCH(A10,'4. Base Mestre (845 Produtos)'!$A$4:$A$848,0),IF(ISNUMBER(MATCH(B10,'4. Base Mestre (845 Produtos)'!$B$4:$B$848,0)),MATCH(B10,'4. Base Mestre (845 Produtos)'!$B$4:$B$848,0),0))>0,INDEX('4. Base Mestre (845 Produtos)'!$S$4:$S$848,IF(ISNUMBER(MATCH(A10,'4. Base Mestre (845 Produtos)'!$A$4:$A$848,0)),MATCH(A10,'4. Base Mestre (845 Produtos)'!$A$4:$A$848,0),IF(ISNUMBER(MATCH(B10,'4. Base Mestre (845 Produtos)'!$B$4:$B$848,0)),MATCH(B10,'4. Base Mestre (845 Produtos)'!$B$4:$B$848,0),0))),IF(ISNUMBER(MATCH(D10,'3. Dicionario Principios Ativos'!$A$4:$A$245,0)),INDEX('3. Dicionario Principios Ativos'!$L$4:$L$245,MATCH(D10,'3. Dicionario Principios Ativos'!$A$4:$A$245,0)),"Verificar NCM"))) -> Beneficiado (Lei 10.925/04): 0% até Mar/26 | 0,925% Real / 0,365% Pres. pós-Abr/26 (LC 224/25) | W10: =IF(B10="","",IF(IF(ISNUMBER(MATCH(A10,'4. Base Mestre (845 Produtos)'!$A$4:$A$848,0)),MATCH(A10,'4. Base Mestre (845 Produtos)'!$A$4:$A$848,0),IF(ISNUMBER(MATCH(B10,'4. Base Mestre (845 Produtos)'!$B$4:$B$848,0)),MATCH(B10,'4. Base Mestre (845 Produtos)'!$B$4:$B$848,0),0))>0,INDEX('4. Base Mestre (845 Produtos)'!$T$4:$T$848,IF(ISNUMBER(MATCH(A10,'4. Base Mestre (845 Produtos)'!$A$4:$A$848,0)),MATCH(A10,'4. Base Mestre (845 Produtos)'!$A$4:$A$848,0),IF(ISNUMBER(MATCH(B10,'4. Base Mestre (845 Produtos)'!$B$4:$B$848,0)),MATCH(B10,'4. Base Mestre (845 Produtos)'!$B$4:$B$848,0),0))),IF(ISNUMBER(MATCH(D10,'3. Dicionario Principios Ativos'!$A$4:$A$245,0)),INDEX('3. Dicionario Principios Ativos'!$M$4:$M$245,MATCH(D10,'3. Dicionario Principios Ativos'!$A$4:$A$245,0)),"Verificar CST"))) -> Saída: CST 06 (c/ Ajuste M220/M620 pós-Abr/26) | Entrada Revenda: CST 73 | X10: =IF(B10="","",IF(AND(LEFT(M10,8)="CONFORME",LEFT(P10,8)="CONFORME",LEFT(R10,8)="CONFORME",LEFT(S10,8)="CONFORME",LEFT(U10,8)="CONFORME"),"CADASTRO 100% CONFORME — LIBERADO P/ ERP",IF(AND(LEFT(M10,8)="CONFORME",LEFT(P10,8)="CONFORME",LEFT(R10,8)="CONFORME",LEFT(S10,8)="CONFORME",OR(LEFT(U10,7)="ADEQUAR",LEFT(U10,8)="VINCULAR")),"FISCAL E EMBALAGEM OK — ADEQUAR CAMPO MAPA (SIPEAGRO / MARCA)","BLOQUEADO — CORRIGIR DIVERGÊNCIAS APONTADAS ANTES DE LIBERAR NO ERP"))) -> CADASTRO 100% CONFORME — LIBERADO P/ ERP
A11: 233 | B11: TRINCA CAPS 4X5L | C11: L | D11: LAMBDA-CIALOTRINA 250 | E11: 3808.62.90 | F11: 4110 | H11: Cenário 03 [OK]: Lambda-cialotrina em galão 5L (300g a 7,5kg) na NCM 3808.62.90 correta | I11: =IF(B11="","",IF(ISNUMBER(MATCH(A11,'4. Base Mestre (845 Produtos)'!$A$4:$A$848,0)),"Localizado por Código ("&A11&") na Base Mestre",IF(ISNUMBER(MATCH(B11,'4. Base Mestre (845 Produtos)'!$B$4:$B$848,0)),"Localizado por Descrição na Base Mestre",IF(ISNUMBER(MATCH(D11,'3. Dicionario Principios Ativos'!$A$4:$A$245,0)),"Produto Novo — Validado pelo Dicionário de P.A.","Não Localizado — Revisar Código/P.A.")))) -> Localizado por Código (233) na Base Mestre | J11: =IF(B11="","",IF(IF(ISNUMBER(MATCH(A11,'4. Base Mestre (845 Produtos)'!$A$4:$A$848,0)),MATCH(A11,'4. Base Mestre (845 Produtos)'!$A$4:$A$848,0),IF(ISNUMBER(MATCH(B11,'4. Base Mestre (845 Produtos)'!$B$4:$B$848,0)),MATCH(B11,'4. Base Mestre (845 Produtos)'!$B$4:$B$848,0),0))>0,INDEX('4. Base Mestre (845 Produtos)'!$I$4:$I$848,IF(ISNUMBER(MATCH(A11,'4. Base Mestre (845 Produtos)'!$A$4:$A$848,0)),MATCH(A11,'4. Base Mestre (845 Produtos)'!$A$4:$A$848,0),IF(ISNUMBER(MATCH(B11,'4. Base Mestre (845 Produtos)'!$B$4:$B$848,0)),MATCH(B11,'4. Base Mestre (845 Produtos)'!$B$4:$B$848,0),0))),IF(ISNUMBER(MATCH(D11,'3. Dicionario Principios Ativos'!$A$4:$A$245,0)),INDEX('3. Dicionario Principios Ativos'!$B$4:$B$245,MATCH(D11,'3. Dicionario Principios Ativos'!$A$4:$A$245,0)),"Revisar Classificação"))) -> Defensivos — Inseticida | K11: =IF(B11="","",IF(G11<>"",G11,IF(OR(ISNUMBER(SEARCH("PRINCIPIO ATIVO",B11)),ISNUMBER(SEARCH("PRINC. ATIVO",B11)),ISNUMBER(SEARCH("PR. ATIVO",B11)),ISNUMBER(SEARCH("PR.AT.",B11)),ISNUMBER(SEARCH("(P.A",B11)),ISNUMBER(SEARCH("(P. A",B11))),0,IF(OR(ISNUMBER(SEARCH("0,100KG",B11)),ISNUMBER(SEARCH("0,1KG",B11)),ISNUMBER(SEARCH("0,100L",B11))),0.1,IF(OR(ISNUMBER(SEARCH("0,200L",B11)),ISNUMBER(SEARCH("0,2L",B11)),ISNUMBER(SEARCH("0,200KG",B11)),ISNUMBER(SEARCH("0,2KG",B11))),0.2,IF(OR(ISNUMBER(SEARCH("0,240KG",B11)),ISNUMBER(SEARCH("0,250L",B11))),0.24,IF(OR(ISNUMBER(SEARCH("0,300KG",B11)),ISNUMBER(SEARCH("0,3KG",B11))),0.3,IF(OR(ISNUMBER(SEARCH("0,500L",B11)),ISNUMBER(SEARCH("0,5L",B11)),ISNUMBER(SEARCH("0,5KG",B11))),0.5,IF(ISNUMBER(SEARCH("0,8KG",B11)),0.8,IF(OR(ISNUMBER(SEARCH("1,5L",B11)),ISNUMBER(SEARCH("1,5KG",B11))),1.5,IF(OR(ISNUMBER(SEARCH("1,75L",B11)),ISNUMBER(SEARCH("1,8L",B11)),ISNUMBER(SEARCH("1.8L",B11))),1.8,IF(ISNUMBER(SEARCH("4,5KG",B11)),4.5,IF(ISNUMBER(SEARCH("7,5KG",B11)),7.5,IF(OR(ISNUMBER(SEARCH("1000L",B11)),ISNUMBER(SEARCH("1000KG",B11)),ISNUMBER(SEARCH("1.000KG",B11)),ISNUMBER(SEARCH("1.000L",B11)),ISNUMBER(SEARCH("1000 KG",B11)),ISNUMBER(SEARCH("GRANEL",B11)),ISNUMBER(SEARCH("(TON)",B11))),1000,IF(ISNUMBER(SEARCH("200L",B11)),200,IF(OR(ISNUMBER(SEARCH("25KG",B11)),ISNUMBER(SEARCH("25L",B11))),25,IF(OR(ISNUMBER(SEARCH("20L",B11)),ISNUMBER(SEARCH("20KG",B11))),20,IF(ISNUMBER(SEARCH("15KG",B11)),15,IF(OR(ISNUMBER(SEARCH("10L",B11)),ISNUMBER(SEARCH("10KG",B11))),10,IF(OR(ISNUMBER(SEARCH("5L",B11)),ISNUMBER(SEARCH("5KG",B11)),ISNUMBER(SEARCH("5LT",B11))),5,IF(OR(ISNUMBER(SEARCH("3KG",B11)),ISNUMBER(SEARCH("3L",B11))),3,IF(OR(ISNUMBER(SEARCH("2L",B11)),ISNUMBER(SEARCH("2KG",B11))),2,IF(OR(ISNUMBER(SEARCH("1L",B11)),ISNUMBER(SEARCH("1KG",B11)),ISNUMBER(SEARCH("1LT",B11))),1,IF(IF(ISNUMBER(MATCH(A11,'4. Base Mestre (845 Produtos)'!$A$4:$A$848,0)),MATCH(A11,'4. Base Mestre (845 Produtos)'!$A$4:$A$848,0),IF(ISNUMBER(MATCH(B11,'4. Base Mestre (845 Produtos)'!$B$4:$B$848,0)),MATCH(B11,'4. Base Mestre (845 Produtos)'!$B$4:$B$848,0),0))>0,INDEX('4. Base Mestre (845 Produtos)'!$D$4:$D$848,IF(ISNUMBER(MATCH(A11,'4. Base Mestre (845 Produtos)'!$A$4:$A$848,0)),MATCH(A11,'4. Base Mestre (845 Produtos)'!$A$4:$A$848,0),IF(ISNUMBER(MATCH(B11,'4. Base Mestre (845 Produtos)'!$B$4:$B$848,0)),MATCH(B11,'4. Base Mestre (845 Produtos)'!$B$4:$B$848,0),0))),1)))))))))))))))))))))))) -> 5 | L11: =IF(B11="","",IF(OR(ISNUMBER(SEARCH("KG",B11)),ISNUMBER(SEARCH("GR",B11))),"KG",IF(OR(ISNUMBER(SEARCH("0,200L",B11)),ISNUMBER(SEARCH("0,2L",B11)),ISNUMBER(SEARCH("0,5L",B11)),ISNUMBER(SEARCH("1,5L",B11)),ISNUMBER(SEARCH("1,8L",B11)),ISNUMBER(SEARCH("1.8L",B11)),ISNUMBER(SEARCH("1L",B11)),ISNUMBER(SEARCH("2L",B11)),ISNUMBER(SEARCH("3L",B11)),ISNUMBER(SEARCH("5L",B11)),ISNUMBER(SEARCH("10L",B11)),ISNUMBER(SEARCH("20L",B11)),ISNUMBER(SEARCH("25L",B11)),ISNUMBER(SEARCH("200L",B11)),ISNUMBER(SEARCH("1000L",B11)),ISNUMBER(SEARCH("LT",B11))),"L",IF(IF(ISNUMBER(MATCH(A11,'4. Base Mestre (845 Produtos)'!$A$4:$A$848,0)),MATCH(A11,'4. Base Mestre (845 Produtos)'!$A$4:$A$848,0),IF(ISNUMBER(MATCH(B11,'4. Base Mestre (845 Produtos)'!$B$4:$B$848,0)),MATCH(B11,'4. Base Mestre (845 Produtos)'!$B$4:$B$848,0),0))>0,INDEX('4. Base Mestre (845 Produtos)'!$E$4:$E$848,IF(ISNUMBER(MATCH(A11,'4. Base Mestre (845 Produtos)'!$A$4:$A$848,0)),MATCH(A11,'4. Base Mestre (845 Produtos)'!$A$4:$A$848,0),IF(ISNUMBER(MATCH(B11,'4. Base Mestre (845 Produtos)'!$B$4:$B$848,0)),MATCH(B11,'4. Base Mestre (845 Produtos)'!$B$4:$B$848,0),0))),C11)))) -> L | M11: =IF(B11="","",IF(C11=L11,"CONFORME — Unidade ("&C11&") compatível c/ Embalagem","DIVERGENTE — Embalagem em "&L11&", mas cadastrado em "&C11)) -> CONFORME — Unidade (L) compatível c/ Embalagem | N11: =IF(B11="","",IF(K11=0,"Granel / Produto Técnico (Sem Embalagem Comercial)",IF(K11<=0.3001,"Faixa 1 TIPI: Até 300g/mL (3808.61.00 / 3105.10.00)",IF(K11<=7.5001,"Faixa 2 TIPI: De 300g a 7,5kg/L (3808.62.90 / 3105.10.00)",IF(K11<=10.0001,"Faixa 3 TIPI: De 7,5kg a 10kg/L (3808.69.90 / 3105.10.00)","Faixa 4 TIPI: Acima de 10kg/L (3808.69.90 / Cap. 31 Geral)"))))) -> Faixa 2 TIPI: De 300g a 7,5kg/L (3808.62.90 / 3105.10.00) | O11: =IF(B11="","",IF(IF(ISNUMBER(MATCH(A11,'4. Base Mestre (845 Produtos)'!$A$4:$A$848,0)),MATCH(A11,'4. Base Mestre (845 Produtos)'!$A$4:$A$848,0),IF(ISNUMBER(MATCH(B11,'4. Base Mestre (845 Produtos)'!$B$4:$B$848,0)),MATCH(B11,'4. Base Mestre (845 Produtos)'!$B$4:$B$848,0),0))>0,INDEX('4. Base Mestre (845 Produtos)'!$H$4:$H$848,IF(ISNUMBER(MATCH(A11,'4. Base Mestre (845 Produtos)'!$A$4:$A$848,0)),MATCH(A11,'4. Base Mestre (845 Produtos)'!$A$4:$A$848,0),IF(ISNUMBER(MATCH(B11,'4. Base Mestre (845 Produtos)'!$B$4:$B$848,0)),MATCH(B11,'4. Base Mestre (845 Produtos)'!$B$4:$B$848,0),0))),IF(ISNUMBER(MATCH(D11,'3. Dicionario Principios Ativos'!$A$4:$A$245,0)),INDEX('3. Dicionario Principios Ativos'!$A$4:$A$245,MATCH(D11,'3. Dicionario Principios Ativos'!$A$4:$A$245,0)),D11))) -> LAMBDA-CIALOTRINA 250 | P11: =IF(B11="","",IF(D11=O11,"CONFORME — Princípio Ativo Validado","DIVERGENTE — Substituir por: "&O11)) -> CONFORME — Princípio Ativo Validado | Q11: =IF(B11="","",IF(IF(IF(ISNUMBER(MATCH(A11,'4. Base Mestre (845 Produtos)'!$A$4:$A$848,0)),MATCH(A11,'4. Base Mestre (845 Produtos)'!$A$4:$A$848,0),IF(ISNUMBER(MATCH(B11,'4. Base Mestre (845 Produtos)'!$B$4:$B$848,0)),MATCH(B11,'4. Base Mestre (845 Produtos)'!$B$4:$B$848,0),0))>0,INDEX('4. Base Mestre (845 Produtos)'!$J$4:$J$848,IF(ISNUMBER(MATCH(A11,'4. Base Mestre (845 Produtos)'!$A$4:$A$848,0)),MATCH(A11,'4. Base Mestre (845 Produtos)'!$A$4:$A$848,0),IF(ISNUMBER(MATCH(B11,'4. Base Mestre (845 Produtos)'!$B$4:$B$848,0)),MATCH(B11,'4. Base Mestre (845 Produtos)'!$B$4:$B$848,0),0)))="SIM",IF(ISNUMBER(MATCH(D11,'3. Dicionario Principios Ativos'!$A$4:$A$245,0)),INDEX('3. Dicionario Principios Ativos'!$C$4:$C$245,MATCH(D11,'3. Dicionario Principios Ativos'!$A$4:$A$245,0))="SIM",FALSE())),IF(AND(K11>0,K11<=0.3001),"3808.61.00",IF(AND(K11>0.3001,K11<=7.5001),"3808.62.90","3808.69.90")),IF(AND(LEFT(IF(IF(ISNUMBER(MATCH(A11,'4. Base Mestre (845 Produtos)'!$A$4:$A$848,0)),MATCH(A11,'4. Base Mestre (845 Produtos)'!$A$4:$A$848,0),IF(ISNUMBER(MATCH(B11,'4. Base Mestre (845 Produtos)'!$B$4:$B$848,0)),MATCH(B11,'4. Base Mestre (845 Produtos)'!$B$4:$B$848,0),0))>0,INDEX('4. Base Mestre (845 Produtos)'!$L$4:$L$848,IF(ISNUMBER(MATCH(A11,'4. Base Mestre (845 Produtos)'!$A$4:$A$848,0)),MATCH(A11,'4. Base Mestre (845 Produtos)'!$A$4:$A$848,0),IF(ISNUMBER(MATCH(B11,'4. Base Mestre (845 Produtos)'!$B$4:$B$848,0)),MATCH(B11,'4. Base Mestre (845 Produtos)'!$B$4:$B$848,0),0))),IF(ISNUMBER(MATCH(D11,'3. Dicionario Principios Ativos'!$A$4:$A$245,0)),INDEX('3. Dicionario Principios Ativos'!$D$4:$D$245,MATCH(D11,'3. Dicionario Principios Ativos'!$A$4:$A$245,0)),E11)),2)="31",E11="3105.10.00",K11>0,K11<=10.0001),"3105.10.00",IF(AND(IF(IF(ISNUMBER(MATCH(A11,'4. Base Mestre (845 Produtos)'!$A$4:$A$848,0)),MATCH(A11,'4. Base Mestre (845 Produtos)'!$A$4:$A$848,0),IF(ISNUMBER(MATCH(B11,'4. Base Mestre (845 Produtos)'!$B$4:$B$848,0)),MATCH(B11,'4. Base Mestre (845 Produtos)'!$B$4:$B$848,0),0))>0,INDEX('4. Base Mestre (845 Produtos)'!$L$4:$L$848,IF(ISNUMBER(MATCH(A11,'4. Base Mestre (845 Produtos)'!$A$4:$A$848,0)),MATCH(A11,'4. Base Mestre (845 Produtos)'!$A$4:$A$848,0),IF(ISNUMBER(MATCH(B11,'4. Base Mestre (845 Produtos)'!$B$4:$B$848,0)),MATCH(B11,'4. Base Mestre (845 Produtos)'!$B$4:$B$848,0),0))),IF(ISNUMBER(MATCH(D11,'3. Dicionario Principios Ativos'!$A$4:$A$245,0)),INDEX('3. Dicionario Principios Ativos'!$D$4:$D$245,MATCH(D11,'3. Dicionario Principios Ativos'!$A$4:$A$245,0)),E11))="3105.10.00",K11>10.0001),"3105.90.90",IF(IF(ISNUMBER(MATCH(A11,'4. Base Mestre (845 Produtos)'!$A$4:$A$848,0)),MATCH(A11,'4. Base Mestre (845 Produtos)'!$A$4:$A$848,0),IF(ISNUMBER(MATCH(B11,'4. Base Mestre (845 Produtos)'!$B$4:$B$848,0)),MATCH(B11,'4. Base Mestre (845 Produtos)'!$B$4:$B$848,0),0))>0,INDEX('4. Base Mestre (845 Produtos)'!$L$4:$L$848,IF(ISNUMBER(MATCH(A11,'4. Base Mestre (845 Produtos)'!$A$4:$A$848,0)),MATCH(A11,'4. Base Mestre (845 Produtos)'!$A$4:$A$848,0),IF(ISNUMBER(MATCH(B11,'4. Base Mestre (845 Produtos)'!$B$4:$B$848,0)),MATCH(B11,'4. Base Mestre (845 Produtos)'!$B$4:$B$848,0),0))),IF(ISNUMBER(MATCH(D11,'3. Dicionario Principios Ativos'!$A$4:$A$245,0)),INDEX('3. Dicionario Principios Ativos'!$D$4:$D$245,MATCH(D11,'3. Dicionario Principios Ativos'!$A$4:$A$245,0)),E11)))))) -> 3808.62.90 | R11: =IF(B11="","",IF(OR(E11=Q11,AND(Q11="3002.49.99",E11="3002.90.00")),"CONFORME — NCM "&E11&" Correta na TIPI","DIVERGENTE — Substituir "&E11&" por "&Q11)) -> CONFORME — NCM 3808.62.90 Correta na TIPI | S11: =IF(B11="","",IF(AND(E11="3808.61.00",OR(K11>0.3001,K11=0)),"INCOMPATÍVEL — NCM 3808.61.00 exige emb. <= 0,3kg/L (Emb. atual: "&K11&" "&L11&" -> usar "&Q11&")",IF(AND(LEFT(E11,7)="3808.62",OR(K11<=0.3001,K11>7.5001)),"INCOMPATÍVEL — NCM 3808.62 exige emb. de 0,3 a 7,5kg/L (Emb. atual: "&K11&" "&L11&" -> usar "&Q11&")",IF(AND(LEFT(E11,7)="3808.69",K11>0,K11<=7.5001),"INCOMPATÍVEL — NCM 3808.69 exige emb. > 7,5kg/L (Emb. atual: "&K11&" "&L11&" -> usar "&Q11&")",IF(AND(LEFT(Q11,6)="3808.6",LEFT(E11,6)<>"3808.6"),"INCOMPATÍVEL — Molécula Nota Subpos. 2 c/ emb. "&K11&" "&L11&" exige NCM "&Q11,IF(AND(OR(E11="3808.91.19",E11="3808.92.19",E11="3808.93.19",E11="3808.99.19"),K11>=1),"INCOMPATÍVEL — Subitem .19 (Domissanitário) vedado p/ emb. agrícola de "&K11&" "&L11,IF(AND(E11="3105.10.00",K11>10.0001),"INCOMPATÍVEL — NCM 3105.10.00 exige peso bruto <= 10kg (Emb. atual: "&K11&" "&L11&" -> usar 3105.90.90)",IF(AND(LEFT(E11,2)="29",LEFT(Q11,4)="3808",K11>0),"INCOMPATÍVEL — Produto formulado em emb. comercial ("&K11&" "&L11&") vedado no Cap. 29 -> usar "&Q11,"CONFORME — Embalagem ("&K11&" "&L11&") compatível c/ a NCM")))))))) -> CONFORME — Embalagem (5 L) compatível c/ a NCM | T11: =IF(B11="","",IF(IF(ISNUMBER(MATCH(A11,'4. Base Mestre (845 Produtos)'!$A$4:$A$848,0)),MATCH(A11,'4. Base Mestre (845 Produtos)'!$A$4:$A$848,0),IF(ISNUMBER(MATCH(B11,'4. Base Mestre (845 Produtos)'!$B$4:$B$848,0)),MATCH(B11,'4. Base Mestre (845 Produtos)'!$B$4:$B$848,0),0))>0,INDEX('4. Base Mestre (845 Produtos)'!$P$4:$P$848,IF(ISNUMBER(MATCH(A11,'4. Base Mestre (845 Produtos)'!$A$4:$A$848,0)),MATCH(A11,'4. Base Mestre (845 Produtos)'!$A$4:$A$848,0),IF(ISNUMBER(MATCH(B11,'4. Base Mestre (845 Produtos)'!$B$4:$B$848,0)),MATCH(B11,'4. Base Mestre (845 Produtos)'!$B$4:$B$848,0),0))),IF(ISNUMBER(MATCH(D11,'3. Dicionario Principios Ativos'!$A$4:$A$245,0)),INDEX('3. Dicionario Principios Ativos'!$K$4:$K$245,MATCH(D11,'3. Dicionario Principios Ativos'!$A$4:$A$245,0)),"VERIFICAR BULA"))) -> 4110 | U11: =IF(B11="","",IF(ISNUMBER(SEARCH("ISENTO",T11)),IF(OR(F11=0,F11="0",F11="ISENTO",F11=""),"CONFORME (DISPENSADO) — Isento pelo Ato SDA/MAPA nº 104/2017","INCORRETO — Produto isento de registro MAPA (usar 0 ou ISENTO)"),IF(ISNUMBER(SEARCH("SIPEAGRO",T11)),IF(ISNUMBER(SEARCH("-",F11)),"CONFORME — Registro SIPEAGRO ("&F11&") Preenchido","ADEQUAR P/ SIPEAGRO — Substituir 0 pelo Registro (UF-XXXXX-XXXXX.X)"),IF(ISNUMBER(SEARCH("VINCULAR",T11)),IF(AND(F11<>0,F11<>"0",F11<>""),"INCORRETO / TROCADO — Código "&F11&" pertence a outro produto (Vincular bula da marca)","VINCULAR MARCA — Cadastro de P.A. s/ marca fixa (Vincular registro na NF-e)"),IF(OR(F11=0,F11="0",F11=""),"AUSENTE (ZERO) — Preencher Registro Oficial MAPA nº "&T11,IF(TEXT(F11,"0")=TEXT(T11,"0"),"CONFORME — Registro MAPA nº "&T11&" Validado na Bula","INCORRETO / TROCADO — Substituir "&F11&" pelo Registro Oficial nº "&T11)))))) -> CONFORME — Registro MAPA nº 4110 Validado na Bula | V11: =IF(B11="","",IF(IF(ISNUMBER(MATCH(A11,'4. Base Mestre (845 Produtos)'!$A$4:$A$848,0)),MATCH(A11,'4. Base Mestre (845 Produtos)'!$A$4:$A$848,0),IF(ISNUMBER(MATCH(B11,'4. Base Mestre (845 Produtos)'!$B$4:$B$848,0)),MATCH(B11,'4. Base Mestre (845 Produtos)'!$B$4:$B$848,0),0))>0,INDEX('4. Base Mestre (845 Produtos)'!$S$4:$S$848,IF(ISNUMBER(MATCH(A11,'4. Base Mestre (845 Produtos)'!$A$4:$A$848,0)),MATCH(A11,'4. Base Mestre (845 Produtos)'!$A$4:$A$848,0),IF(ISNUMBER(MATCH(B11,'4. Base Mestre (845 Produtos)'!$B$4:$B$848,0)),MATCH(B11,'4. Base Mestre (845 Produtos)'!$B$4:$B$848,0),0))),IF(ISNUMBER(MATCH(D11,'3. Dicionario Principios Ativos'!$A$4:$A$245,0)),INDEX('3. Dicionario Principios Ativos'!$L$4:$L$245,MATCH(D11,'3. Dicionario Principios Ativos'!$A$4:$A$245,0)),"Verificar NCM"))) -> Beneficiado (Lei 10.925/04): 0% até Mar/26 | 0,925% Real / 0,365% Pres. pós-Abr/26 (LC 224/25) | W11: =IF(B11="","",IF(IF(ISNUMBER(MATCH(A11,'4. Base Mestre (845 Produtos)'!$A$4:$A$848,0)),MATCH(A11,'4. Base Mestre (845 Produtos)'!$A$4:$A$848,0),IF(ISNUMBER(MATCH(B11,'4. Base Mestre (845 Produtos)'!$B$4:$B$848,0)),MATCH(B11,'4. Base Mestre (845 Produtos)'!$B$4:$B$848,0),0))>0,INDEX('4. Base Mestre (845 Produtos)'!$T$4:$T$848,IF(ISNUMBER(MATCH(A11,'4. Base Mestre (845 Produtos)'!$A$4:$A$848,0)),MATCH(A11,'4. Base Mestre (845 Produtos)'!$A$4:$A$848,0),IF(ISNUMBER(MATCH(B11,'4. Base Mestre (845 Produtos)'!$B$4:$B$848,0)),MATCH(B11,'4. Base Mestre (845 Produtos)'!$B$4:$B$848,0),0))),IF(ISNUMBER(MATCH(D11,'3. Dicionario Principios Ativos'!$A$4:$A$245,0)),INDEX('3. Dicionario Principios Ativos'!$M$4:$M$245,MATCH(D11,'3. Dicionario Principios Ativos'!$A$4:$A$245,0)),"Verificar CST"))) -> Saída: CST 06 (c/ Ajuste M220/M620 pós-Abr/26) | Entrada Revenda: CST 73 | X11: =IF(B11="","",IF(AND(LEFT(M11,8)="CONFORME",LEFT(P11,8)="CONFORME",LEFT(R11,8)="CONFORME",LEFT(S11,8)="CONFORME",LEFT(U11,8)="CONFORME"),"CADASTRO 100% CONFORME — LIBERADO P/ ERP",IF(AND(LEFT(M11,8)="CONFORME",LEFT(P11,8)="CONFORME",LEFT(R11,8)="CONFORME",LEFT(S11,8)="CONFORME",OR(LEFT(U11,7)="ADEQUAR",LEFT(U11,8)="VINCULAR")),"FISCAL E EMBALAGEM OK — ADEQUAR CAMPO MAPA (SIPEAGRO / MARCA)","BLOQUEADO — CORRIGIR DIVERGÊNCIAS APONTADAS ANTES DE LIBERAR NO ERP"))) -> CADASTRO 100% CONFORME — LIBERADO P/ ERP
